Workbook

Sheet Mi Sprint
A1: OPERACIONES DEL MES
A2: # | B2: Producto | C2: Prima/año € | D2: Edad | E2: PVM | F2: Pago € | G2: Com.Básica € | H2: Riesgo
A3: 1 | B3: Salud Completo | C3: 1180 | E3: =IF(ISBLANK(B3),"", IF(B3="Salud Completo",C3*1.5, IF(B3="Salud Completo Copago",C3*2, IF(B3="Salud Completo Copago Autónomo",C3*1.2, IF(B3="Contigo Senior",C3*3, IF(B3="Contigo Familia",C3*4, IF(B3="Contigo Autónomo (ILT)",C3*2, IF(B3="Plan Creciente SIALP",C3*1, IF(B3="MiHogar Seguro",C3*1.5, IF(B3="Líder Plus Accidentes",C3*4, IF(B3="Seguro Comercio y Oficinas - CASER",C3*0.5, IF(B3="Seguro Responsabilidad Civil - CASER",C3*0.4,0)))))))))))) -> 1770 | F3: =IF(ISBLANK(B3),"", IF(B3="Salud Completo",C3*0.16, IF(B3="Salud Completo Copago",C3*0.16, IF(B3="Salud Completo Copago Autónomo",C3*0.16, IF(B3="Contigo Senior", IF(D3="55-70 años",C3*1, IF(D3="71-75 años",C3*0.82, IF(D3="76-80 años",C3*0.7,0))), IF(B3="Contigo Familia",C3*1.5, IF(B3="Contigo Autónomo (ILT)",C3*0.75, IF(B3="Plan Creciente SIALP",C3*0.27, IF(B3="MiHogar Seguro",C3*1, IF(B3="Líder Plus Accidentes",C3*1.8, IF(B3="Seguro Comercio y Oficinas - CASER",C3*0.21, IF(B3="Seguro Responsabilidad Civil - CASER",C3*0.18,0)))))))))))) -> 188.8 | G3: =IF(ISBLANK(B3),"", IF(B3="Salud Completo",F3*0.0112/12, IF(B3="Salud Completo Copago",F3*0.0112/12, IF(B3="Salud Completo Copago Autónomo",F3*0.0112/12, IF(B3="Contigo Senior", IF(D3="55-70 años",F3*0.07/12, IF(D3="71-75 años",F3*0.0574/12, IF(D3="76-80 años",F3*0.049/12,0))), IF(B3="Contigo Familia",F3*0.105/12, IF(B3="Contigo Autónomo (ILT)",F3*0.105/12, IF(B3="Plan Creciente SIALP",F3*0.0189, IF(B3="MiHogar Seguro",F3*0.042/12, IF(B3="Líder Plus Accidentes",F3*0.25/12, IF(B3="Seguro Comercio y Oficinas - CASER",F3*0.21/12, IF(B3="Seguro Responsabilidad Civil - CASER",F3*0.18/12,0)))))))))))) -> 0.17621333 | H3: =IF(ISBLANK(B3),"", IF(OR(B3="Salud Completo",B3="Salud Completo Copago",B3="Salud Completo Copago Autónomo", B3="Contigo Senior",B3="Contigo Familia",B3="Contigo Autónomo (ILT)", B3="MiHogar Seguro",B3="Líder Plus Accidentes"),"✅","❌")) -> ✅
A4: 2 | B4: Contigo Senior | C4: 720 | D4: 76-80 años | E4: =IF(ISBLANK(B4),"", IF(B4="Salud Completo",C4*1.5, IF(B4="Salud Completo Copago",C4*2, IF(B4="Salud Completo Copago Autónomo",C4*1.2, IF(B4="Contigo Senior",C4*3, IF(B4="Contigo Familia",C4*4, IF(B4="Contigo Autónomo (ILT)",C4*2, IF(B4="Plan Creciente SIALP",C4*1, IF(B4="MiHogar Seguro",C4*1.5, IF(B4="Líder Plus Accidentes",C4*4, IF(B4="Seguro Comercio y Oficinas - CASER",C4*0.5, IF(B4="Seguro Responsabilidad Civil - CASER",C4*0.4,0)))))))))))) -> 2160 | F4: =IF(ISBLANK(B4),"", IF(B4="Salud Completo",C4*0.16, IF(B4="Salud Completo Copago",C4*0.16, IF(B4="Salud Completo Copago Autónomo",C4*0.16, IF(B4="Contigo Senior", IF(D4="55-70 años",C4*1, IF(D4="71-75 años",C4*0.82, IF(D4="76-80 años",C4*0.7,0))), IF(B4="Contigo Familia",C4*1.5, IF(B4="Contigo Autónomo (ILT)",C4*0.75, IF(B4="Plan Creciente SIALP",C4*0.27, IF(B4="MiHogar Seguro",C4*1, IF(B4="Líder Plus Accidentes",C4*1.8, IF(B4="Seguro Comercio y Oficinas - CASER",C4*0.21, IF(B4="Seguro Responsabilidad Civil - CASER",C4*0.18,0)))))))))))) -> 504 | G4: =IF(ISBLANK(B4),"", IF(B4="Salud Completo",F4*0.0112/12, IF(B4="Salud Completo Copago",F4*0.0112/12, IF(B4="Salud Completo Copago Autónomo",F4*0.0112/12, IF(B4="Contigo Senior", IF(D4="55-70 años",F4*0.07/12, IF(D4="71-75 años",F4*0.0574/12, IF(D4="76-80 años",F4*0.049/12,0))), IF(B4="Contigo Familia",F4*0.105/12, IF(B4="Contigo Autónomo (ILT)",F4*0.105/12, IF(B4="Plan Creciente SIALP",F4*0.0189, IF(B4="MiHogar Seguro",F4*0.042/12, IF(B4="Líder Plus Accidentes",F4*0.25/12, IF(B4="Seguro Comercio y Oficinas - CASER",F4*0.21/12, IF(B4="Seguro Responsabilidad Civil - CASER",F4*0.18/12,0)))))))))))) -> 2.058 | H4: =IF(ISBLANK(B4),"", IF(OR(B4="Salud Completo",B4="Salud Completo Copago",B4="Salud Completo Copago Autónomo", B4="Contigo Senior",B4="Contigo Familia",B4="Contigo Autónomo (ILT)", B4="MiHogar Seguro",B4="Líder Plus Accidentes"),"✅","❌")) -> ✅
A5: 3 | B5: Plan Creciente SIALP | C5: 2000 | E5: =IF(ISBLANK(B5),"", IF(B5="Salud Completo",C5*1.5, IF(B5="Salud Completo Copago",C5*2, IF(B5="Salud Completo Copago Autónomo",C5*1.2, IF(B5="Contigo Senior",C5*3, IF(B5="Contigo Familia",C5*4, IF(B5="Contigo Autónomo (ILT)",C5*2, IF(B5="Plan Creciente SIALP",C5*1, IF(B5="MiHogar Seguro",C5*1.5, IF(B5="Líder Plus Accidentes",C5*4, IF(B5="Seguro Comercio y Oficinas - CASER",C5*0.5, IF(B5="Seguro Responsabilidad Civil - CASER",C5*0.4,0)))))))))))) -> 2000 | F5: =IF(ISBLANK(B5),"", IF(B5="Salud Completo",C5*0.16, IF(B5="Salud Completo Copago",C5*0.16, IF(B5="Salud Completo Copago Autónomo",C5*0.16, IF(B5="Contigo Senior", IF(D5="55-70 años",C5*1, IF(D5="71-75 años",C5*0.82, IF(D5="76-80 años",C5*0.7,0))), IF(B5="Contigo Familia",C5*1.5, IF(B5="Contigo Autónomo (ILT)",C5*0.75, IF(B5="Plan Creciente SIALP",C5*0.27, IF(B5="MiHogar Seguro",C5*1, IF(B5="Líder Plus Accidentes",C5*1.8, IF(B5="Seguro Comercio y Oficinas - CASER",C5*0.21, IF(B5="Seguro Responsabilidad Civil - CASER",C5*0.18,0)))))))))))) -> 540 | G5: =IF(ISBLANK(B5),"", IF(B5="Salud Completo",F5*0.0112/12, IF(B5="Salud Completo Copago",F5*0.0112/12, IF(B5="Salud Completo Copago Autónomo",F5*0.0112/12, IF(B5="Contigo Senior", IF(D5="55-70 años",F5*0.07/12, IF(D5="71-75 años",F5*0.0574/12, IF(D5="76-80 años",F5*0.049/12,0))), IF(B5="Contigo Familia",F5*0.105/12, IF(B5="Contigo Autónomo (ILT)",F5*0.105/12, IF(B5="Plan Creciente SIALP",F5*0.0189, IF(B5="MiHogar Seguro",F5*0.042/12, IF(B5="Líder Plus Accidentes",F5*0.25/12, IF(B5="Seguro Comercio y Oficinas - CASER",F5*0.21/12, IF(B5="Seguro Responsabilidad Civil - CASER",F5*0.18/12,0)))))))))))) -> 10.206 | H5: =IF(ISBLANK(B5),"", IF(OR(B5="Salud Completo",B5="Salud Completo Copago",B5="Salud Completo Copago Autónomo", B5="Contigo Senior",B5="Contigo Familia",B5="Contigo Autónomo (ILT)", B5="MiHogar Seguro",B5="Líder Plus Accidentes"),"✅","❌")) -> ❌
A6: 4 | E6: =IF(ISBLANK(B6),"", IF(B6="Salud Completo",C6*1.5, IF(B6="Salud Completo Copago",C6*2, IF(B6="Salud Completo Copago Autónomo",C6*1.2, IF(B6="Contigo Senior",C6*3, IF(B6="Contigo Familia",C6*4, IF(B6="Contigo Autónomo (ILT)",C6*2, IF(B6="Plan Creciente SIALP",C6*1, IF(B6="MiHogar Seguro",C6*1.5, IF(B6="Líder Plus Accidentes",C6*4, IF(B6="Seguro Comercio y Oficinas - CASER",C6*0.5, IF(B6="Seguro Responsabilidad Civil - CASER",C6*0.4,0)))))))))))) | F6: =IF(ISBLANK(B6),"", IF(B6="Salud Completo",C6*0.16, IF(B6="Salud Completo Copago",C6*0.16, IF(B6="Salud Completo Copago Autónomo",C6*0.16, IF(B6="Contigo Senior", IF(D6="55-70 años",C6*1, IF(D6="71-75 años",C6*0.82, IF(D6="76-80 años",C6*0.7,0))), IF(B6="Contigo Familia",C6*1.5, IF(B6="Contigo Autónomo (ILT)",C6*0.75, IF(B6="Plan Creciente SIALP",C6*0.27, IF(B6="MiHogar Seguro",C6*1, IF(B6="Líder Plus Accidentes",C6*1.8, IF(B6="Seguro Comercio y Oficinas - CASER",C6*0.21, IF(B6="Seguro Responsabilidad Civil - CASER",C6*0.18,0)))))))))))) | G6: =IF(ISBLANK(B6),"", IF(B6="Salud Completo",F6*0.0112/12, IF(B6="Salud Completo Copago",F6*0.0112/12, IF(B6="Salud Completo Copago Autónomo",F6*0.0112/12, IF(B6="Contigo Senior", IF(D6="55-70 años",F6*0.07/12, IF(D6="71-75 años",F6*0.0574/12, IF(D6="76-80 años",F6*0.049/12,0))), IF(B6="Contigo Familia",F6*0.105/12, IF(B6="Contigo Autónomo (ILT)",F6*0.105/12, IF(B6="Plan Creciente SIALP",F6*0.0189, IF(B6="MiHogar Seguro",F6*0.042/12, IF(B6="Líder Plus Accidentes",F6*0.25/12, IF(B6="Seguro Comercio y Oficinas - CASER",F6*0.21/12, IF(B6="Seguro Responsabilidad Civil - CASER",F6*0.18/12,0)))))))))))) | H6: =IF(ISBLANK(B6),"", IF(OR(B6="Salud Completo",B6="Salud Completo Copago",B6="Salud Completo Copago Autónomo", B6="Contigo Senior",B6="Contigo Familia",B6="Contigo Autónomo (ILT)", B6="MiHogar Seguro",B6="Líder Plus Accidentes"),"✅","❌"))
A7: 5 | E7: =IF(ISBLANK(B7),"", IF(B7="Salud Completo",C7*1.5, IF(B7="Salud Completo Copago",C7*2, IF(B7="Salud Completo Copago Autónomo",C7*1.2, IF(B7="Contigo Senior",C7*3, IF(B7="Contigo Familia",C7*4, IF(B7="Contigo Autónomo (ILT)",C7*2, IF(B7="Plan Creciente SIALP",C7*1, IF(B7="MiHogar Seguro",C7*1.5, IF(B7="Líder Plus Accidentes",C7*4, IF(B7="Seguro Comercio y Oficinas - CASER",C7*0.5, IF(B7="Seguro Responsabilidad Civil - CASER",C7*0.4,0)))))))))))) | F7: =IF(ISBLANK(B7),"", IF(B7="Salud Completo",C7*0.16, IF(B7="Salud Completo Copago",C7*0.16, IF(B7="Salud Completo Copago Autónomo",C7*0.16, IF(B7="Contigo Senior", IF(D7="55-70 años",C7*1, IF(D7="71-75 años",C7*0.82, IF(D7="76-80 años",C7*0.7,0))), IF(B7="Contigo Familia",C7*1.5, IF(B7="Contigo Autónomo (ILT)",C7*0.75, IF(B7="Plan Creciente SIALP",C7*0.27, IF(B7="MiHogar Seguro",C7*1, IF(B7="Líder Plus Accidentes",C7*1.8, IF(B7="Seguro Comercio y Oficinas - CASER",C7*0.21, IF(B7="Seguro Responsabilidad Civil - CASER",C7*0.18,0)))))))))))) | G7: =IF(ISBLANK(B7),"", IF(B7="Salud Completo",F7*0.0112/12, IF(B7="Salud Completo Copago",F7*0.0112/12, IF(B7="Salud Completo Copago Autónomo",F7*0.0112/12, IF(B7="Contigo Senior", IF(D7="55-70 años",F7*0.07/12, IF(D7="71-75 años",F7*0.0574/12, IF(D7="76-80 años",F7*0.049/12,0))), IF(B7="Contigo Familia",F7*0.105/12, IF(B7="Contigo Autónomo (ILT)",F7*0.105/12, IF(B7="Plan Creciente SIALP",F7*0.0189, IF(B7="MiHogar Seguro",F7*0.042/12, IF(B7="Líder Plus Accidentes",F7*0.25/12, IF(B7="Seguro Comercio y Oficinas - CASER",F7*0.21/12, IF(B7="Seguro Responsabilidad Civil - CASER",F7*0.18/12,0)))))))))))) | H7: =IF(ISBLANK(B7),"", IF(OR(B7="Salud Completo",B7="Salud Completo Copago",B7="Salud Completo Copago Autónomo", B7="Contigo Senior",B7="Contigo Familia",B7="Contigo Autónomo (ILT)", B7="MiHogar Seguro",B7="Líder Plus Accidentes"),"✅","❌"))
A8: 6 | E8: =IF(ISBLANK(B8),"", IF(B8="Salud Completo",C8*1.5, IF(B8="Salud Completo Copago",C8*2, IF(B8="Salud Completo Copago Autónomo",C8*1.2, IF(B8="Contigo Senior",C8*3, IF(B8="Contigo Familia",C8*4, IF(B8="Contigo Autónomo (ILT)",C8*2, IF(B8="Plan Creciente SIALP",C8*1, IF(B8="MiHogar Seguro",C8*1.5, IF(B8="Líder Plus Accidentes",C8*4, IF(B8="Seguro Comercio y Oficinas - CASER",C8*0.5, IF(B8="Seguro Responsabilidad Civil - CASER",C8*0.4,0)))))))))))) | F8: =IF(ISBLANK(B8),"", IF(B8="Salud Completo",C8*0.16, IF(B8="Salud Completo Copago",C8*0.16, IF(B8="Salud Completo Copago Autónomo",C8*0.16, IF(B8="Contigo Senior", IF(D8="55-70 años",C8*1, IF(D8="71-75 años",C8*0.82, IF(D8="76-80 años",C8*0.7,0))), IF(B8="Contigo Familia",C8*1.5, IF(B8="Contigo Autónomo (ILT)",C8*0.75, IF(B8="Plan Creciente SIALP",C8*0.27, IF(B8="MiHogar Seguro",C8*1, IF(B8="Líder Plus Accidentes",C8*1.8, IF(B8="Seguro Comercio y Oficinas - CASER",C8*0.21, IF(B8="Seguro Responsabilidad Civil - CASER",C8*0.18,0)))))))))))) | G8: =IF(ISBLANK(B8),"", IF(B8="Salud Completo",F8*0.0112/12, IF(B8="Salud Completo Copago",F8*0.0112/12, IF(B8="Salud Completo Copago Autónomo",F8*0.0112/12, IF(B8="Contigo Senior", IF(D8="55-70 años",F8*0.07/12, IF(D8="71-75 años",F8*0.0574/12, IF(D8="76-80 años",F8*0.049/12,0))), IF(B8="Contigo Familia",F8*0.105/12, IF(B8="Contigo Autónomo (ILT)",F8*0.105/12, IF(B8="Plan Creciente SIALP",F8*0.0189, IF(B8="MiHogar Seguro",F8*0.042/12, IF(B8="Líder Plus Accidentes",F8*0.25/12, IF(B8="Seguro Comercio y Oficinas - CASER",F8*0.21/12, IF(B8="Seguro Responsabilidad Civil - CASER",F8*0.18/12,0)))))))))))) | H8: =IF(ISBLANK(B8),"", IF(OR(B8="Salud Completo",B8="Salud Completo Copago",B8="Salud Completo Copago Autónomo", B8="Contigo Senior",B8="Contigo Familia",B8="Contigo Autónomo (ILT)", B8="MiHogar Seguro",B8="Líder Plus Accidentes"),"✅","❌"))
A9: 7 | E9: =IF(ISBLANK(B9),"", IF(B9="Salud Completo",C9*1.5, IF(B9="Salud Completo Copago",C9*2, IF(B9="Salud Completo Copago Autónomo",C9*1.2, IF(B9="Contigo Senior",C9*3, IF(B9="Contigo Familia",C9*4, IF(B9="Contigo Autónomo (ILT)",C9*2, IF(B9="Plan Creciente SIALP",C9*1, IF(B9="MiHogar Seguro",C9*1.5, IF(B9="Líder Plus Accidentes",C9*4, IF(B9="Seguro Comercio y Oficinas - CASER",C9*0.5, IF(B9="Seguro Responsabilidad Civil - CASER",C9*0.4,0)))))))))))) | F9: =IF(ISBLANK(B9),"", IF(B9="Salud Completo",C9*0.16, IF(B9="Salud Completo Copago",C9*0.16, IF(B9="Salud Completo Copago Autónomo",C9*0.16, IF(B9="Contigo Senior", IF(D9="55-70 años",C9*1, IF(D9="71-75 años",C9*0.82, IF(D9="76-80 años",C9*0.7,0))), IF(B9="Contigo Familia",C9*1.5, IF(B9="Contigo Autónomo (ILT)",C9*0.75, IF(B9="Plan Creciente SIALP",C9*0.27, IF(B9="MiHogar Seguro",C9*1, IF(B9="Líder Plus Accidentes",C9*1.8, IF(B9="Seguro Comercio y Oficinas - CASER",C9*0.21, IF(B9="Seguro Responsabilidad Civil - CASER",C9*0.18,0)))))))))))) | G9: =IF(ISBLANK(B9),"", IF(B9="Salud Completo",F9*0.0112/12, IF(B9="Salud Completo Copago",F9*0.0112/12, IF(B9="Salud Completo Copago Autónomo",F9*0.0112/12, IF(B9="Contigo Senior", IF(D9="55-70 años",F9*0.07/12, IF(D9="71-75 años",F9*0.0574/12, IF(D9="76-80 años",F9*0.049/12,0))), IF(B9="Contigo Familia",F9*0.105/12, IF(B9="Contigo Autónomo (ILT)",F9*0.105/12, IF(B9="Plan Creciente SIALP",F9*0.0189, IF(B9="MiHogar Seguro",F9*0.042/12, IF(B9="Líder Plus Accidentes",F9*0.25/12, IF(B9="Seguro Comercio y Oficinas - CASER",F9*0.21/12, IF(B9="Seguro Responsabilidad Civil - CASER",F9*0.18/12,0)))))))))))) | H9: =IF(ISBLANK(B9),"", IF(OR(B9="Salud Completo",B9="Salud Completo Copago",B9="Salud Completo Copago Autónomo", B9="Contigo Senior",B9="Contigo Familia",B9="Contigo Autónomo (ILT)", B9="MiHogar Seguro",B9="Líder Plus Accidentes"),"✅","❌"))
A10: 8 | E10: =IF(ISBLANK(B10),"", IF(B10="Salud Completo",C10*1.5, IF(B10="Salud Completo Copago",C10*2, IF(B10="Salud Completo Copago Autónomo",C10*1.2, IF(B10="Contigo Senior",C10*3, IF(B10="Contigo Familia",C10*4, IF(B10="Contigo Autónomo (ILT)",C10*2, IF(B10="Plan Creciente SIALP",C10*1, IF(B10="MiHogar Seguro",C10*1.5, IF(B10="Líder Plus Accidentes",C10*4, IF(B10="Seguro Comercio y Oficinas - CASER",C10*0.5, IF(B10="Seguro Responsabilidad Civil - CASER",C10*0.4,0)))))))))))) | F10: =IF(ISBLANK(B10),"", IF(B10="Salud Completo",C10*0.16, IF(B10="Salud Completo Copago",C10*0.16, IF(B10="Salud Completo Copago Autónomo",C10*0.16, IF(B10="Contigo Senior", IF(D10="55-70 años",C10*1, IF(D10="71-75 años",C10*0.82, IF(D10="76-80 años",C10*0.7,0))), IF(B10="Contigo Familia",C10*1.5, IF(B10="Contigo Autónomo (ILT)",C10*0.75, IF(B10="Plan Creciente SIALP",C10*0.27, IF(B10="MiHogar Seguro",C10*1, IF(B10="Líder Plus Accidentes",C10*1.8, IF(B10="Seguro Comercio y Oficinas - CASER",C10*0.21, IF(B10="Seguro Responsabilidad Civil - CASER",C10*0.18,0)))))))))))) | G10: =IF(ISBLANK(B10),"", IF(B10="Salud Completo",F10*0.0112/12, IF(B10="Salud Completo Copago",F10*0.0112/12, IF(B10="Salud Completo Copago Autónomo",F10*0.0112/12, IF(B10="Contigo Senior", IF(D10="55-70 años",F10*0.07/12, IF(D10="71-75 años",F10*0.0574/12, IF(D10="76-80 años",F10*0.049/12,0))), IF(B10="Contigo Familia",F10*0.105/12, IF(B10="Contigo Autónomo (ILT)",F10*0.105/12, IF(B10="Plan Creciente SIALP",F10*0.0189, IF(B10="MiHogar Seguro",F10*0.042/12, IF(B10="Líder Plus Accidentes",F10*0.25/12, IF(B10="Seguro Comercio y Oficinas - CASER",F10*0.21/12, IF(B10="Seguro Responsabilidad Civil - CASER",F10*0.18/12,0)))))))))))) | H10: =IF(ISBLANK(B10),"", IF(OR(B10="Salud Completo",B10="Salud Completo Copago",B10="Salud Completo Copago Autónomo", B10="Contigo Senior",B10="Contigo Familia",B10="Contigo Autónomo (ILT)", B10="MiHogar Seguro",B10="Líder Plus Accidentes"),"✅","❌"))
A11: 9 | E11: =IF(ISBLANK(B11),"", IF(B11="Salud Completo",C11*1.5, IF(B11="Salud Completo Copago",C11*2, IF(B11="Salud Completo Copago Autónomo",C11*1.2, IF(B11="Contigo Senior",C11*3, IF(B11="Contigo Familia",C11*4, IF(B11="Contigo Autónomo (ILT)",C11*2, IF(B11="Plan Creciente SIALP",C11*1, IF(B11="MiHogar Seguro",C11*1.5, IF(B11="Líder Plus Accidentes",C11*4, IF(B11="Seguro Comercio y Oficinas - CASER",C11*0.5, IF(B11="Seguro Responsabilidad Civil - CASER",C11*0.4,0)))))))))))) | F11: =IF(ISBLANK(B11),"", IF(B11="Salud Completo",C11*0.16, IF(B11="Salud Completo Copago",C11*0.16, IF(B11="Salud Completo Copago Autónomo",C11*0.16, IF(B11="Contigo Senior", IF(D11="55-70 años",C11*1, IF(D11="71-75 años",C11*0.82, IF(D11="76-80 años",C11*0.7,0))), IF(B11="Contigo Familia",C11*1.5, IF(B11="Contigo Autónomo (ILT)",C11*0.75, IF(B11="Plan Creciente SIALP",C11*0.27, IF(B11="MiHogar Seguro",C11*1, IF(B11="Líder Plus Accidentes",C11*1.8, IF(B11="Seguro Comercio y Oficinas - CASER",C11*0.21, IF(B11="Seguro Responsabilidad Civil - CASER",C11*0.18,0)))))))))))) | G11: =IF(ISBLANK(B11),"", IF(B11="Salud Completo",F11*0.0112/12, IF(B11="Salud Completo Copago",F11*0.0112/12, IF(B11="Salud Completo Copago Autónomo",F11*0.0112/12, IF(B11="Contigo Senior", IF(D11="55-70 años",F11*0.07/12, IF(D11="71-75 años",F11*0.0574/12, IF(D11="76-80 años",F11*0.049/12,0))), IF(B11="Contigo Familia",F11*0.105/12, IF(B11="Contigo Autónomo (ILT)",F11*0.105/12, IF(B11="Plan Creciente SIALP",F11*0.0189, IF(B11="MiHogar Seguro",F11*0.042/12, IF(B11="Líder Plus Accidentes",F11*0.25/12, IF(B11="Seguro Comercio y Oficinas - CASER",F11*0.21/12, IF(B11="Seguro Responsabilidad Civil - CASER",F11*0.18/12,0)))))))))))) | H11: =IF(ISBLANK(B11),"", IF(OR(B11="Salud Completo",B11="Salud Completo Copago",B11="Salud Completo Copago Autónomo", B11="Contigo Senior",B11="Contigo Familia",B11="Contigo Autónomo (ILT)", B11="MiHogar Seguro",B11="Líder Plus Accidentes"),"✅","❌"))
A12: 10 | E12: =IF(ISBLANK(B12),"", IF(B12="Salud Completo",C12*1.5, IF(B12="Salud Completo Copago",C12*2, IF(B12="Salud Completo Copago Autónomo",C12*1.2, IF(B12="Contigo Senior",C12*3, IF(B12="Contigo Familia",C12*4, IF(B12="Contigo Autónomo (ILT)",C12*2, IF(B12="Plan Creciente SIALP",C12*1, IF(B12="MiHogar Seguro",C12*1.5, IF(B12="Líder Plus Accidentes",C12*4, IF(B12="Seguro Comercio y Oficinas - CASER",C12*0.5, IF(B12="Seguro Responsabilidad Civil - CASER",C12*0.4,0)))))))))))) | F12: =IF(ISBLANK(B12),"", IF(B12="Salud Completo",C12*0.16, IF(B12="Salud Completo Copago",C12*0.16, IF(B12="Salud Completo Copago Autónomo",C12*0.16, IF(B12="Contigo Senior", IF(D12="55-70 años",C12*1, IF(D12="71-75 años",C12*0.82, IF(D12="76-80 años",C12*0.7,0))), IF(B12="Contigo Familia",C12*1.5, IF(B12="Contigo Autónomo (ILT)",C12*0.75, IF(B12="Plan Creciente SIALP",C12*0.27, IF(B12="MiHogar Seguro",C12*1, IF(B12="Líder Plus Accidentes",C12*1.8, IF(B12="Seguro Comercio y Oficinas - CASER",C12*0.21, IF(B12="Seguro Responsabilidad Civil - CASER",C12*0.18,0)))))))))))) | G12: =IF(ISBLANK(B12),"", IF(B12="Salud Completo",F12*0.0112/12, IF(B12="Salud Completo Copago",F12*0.0112/12, IF(B12="Salud Completo Copago Autónomo",F12*0.0112/12, IF(B12="Contigo Senior", IF(D12="55-70 años",F12*0.07/12, IF(D12="71-75 años",F12*0.0574/12, IF(D12="76-80 años",F12*0.049/12,0))), IF(B12="Contigo Familia",F12*0.105/12, IF(B12="Contigo Autónomo (ILT)",F12*0.105/12, IF(B12="Plan Creciente SIALP",F12*0.0189, IF(B12="MiHogar Seguro",F12*0.042/12, IF(B12="Líder Plus Accidentes",F12*0.25/12, IF(B12="Seguro Comercio y Oficinas - CASER",F12*0.21/12, IF(B12="Seguro Responsabilidad Civil - CASER",F12*0.18/12,0)))))))))))) | H12: =IF(ISBLANK(B12),"", IF(OR(B12="Salud Completo",B12="Salud Completo Copago",B12="Salud Completo Copago Autónomo", B12="Contigo Senior",B12="Contigo Familia",B12="Contigo Autónomo (ILT)", B12="MiHogar Seguro",B12="Líder Plus Accidentes"),"✅","❌"))
A13: 11 | E13: =IF(ISBLANK(B13),"", IF(B13="Salud Completo",C13*1.5, IF(B13="Salud Completo Copago",C13*2, IF(B13="Salud Completo Copago Autónomo",C13*1.2, IF(B13="Contigo Senior",C13*3, IF(B13="Contigo Familia",C13*4, IF(B13="Contigo Autónomo (ILT)",C13*2, IF(B13="Plan Creciente SIALP",C13*1, IF(B13="MiHogar Seguro",C13*1.5, IF(B13="Líder Plus Accidentes",C13*4, IF(B13="Seguro Comercio y Oficinas - CASER",C13*0.5, IF(B13="Seguro Responsabilidad Civil - CASER",C13*0.4,0)))))))))))) | F13: =IF(ISBLANK(B13),"", IF(B13="Salud Completo",C13*0.16, IF(B13="Salud Completo Copago",C13*0.16, IF(B13="Salud Completo Copago Autónomo",C13*0.16, IF(B13="Contigo Senior", IF(D13="55-70 años",C13*1, IF(D13="71-75 años",C13*0.82, IF(D13="76-80 años",C13*0.7,0))), IF(B13="Contigo Familia",C13*1.5, IF(B13="Contigo Autónomo (ILT)",C13*0.75, IF(B13="Plan Creciente SIALP",C13*0.27, IF(B13="MiHogar Seguro",C13*1, IF(B13="Líder Plus Accidentes",C13*1.8, IF(B13="Seguro Comercio y Oficinas - CASER",C13*0.21, IF(B13="Seguro Responsabilidad Civil - CASER",C13*0.18,0)))))))))))) | G13: =IF(ISBLANK(B13),"", IF(B13="Salud Completo",F13*0.0112/12, IF(B13="Salud Completo Copago",F13*0.0112/12, IF(B13="Salud Completo Copago Autónomo",F13*0.0112/12, IF(B13="Contigo Senior", IF(D13="55-70 años",F13*0.07/12, IF(D13="71-75 años",F13*0.0574/12, IF(D13="76-80 años",F13*0.049/12,0))), IF(B13="Contigo Familia",F13*0.105/12, IF(B13="Contigo Autónomo (ILT)",F13*0.105/12, IF(B13="Plan Creciente SIALP",F13*0.0189, IF(B13="MiHogar Seguro",F13*0.042/12, IF(B13="Líder Plus Accidentes",F13*0.25/12, IF(B13="Seguro Comercio y Oficinas - CASER",F13*0.21/12, IF(B13="Seguro Responsabilidad Civil - CASER",F13*0.18/12,0)))))))))))) | H13: =IF(ISBLANK(B13),"", IF(OR(B13="Salud Completo",B13="Salud Completo Copago",B13="Salud Completo Copago Autónomo", B13="Contigo Senior",B13="Contigo Familia",B13="Contigo Autónomo (ILT)", B13="MiHogar Seguro",B13="Líder Plus Accidentes"),"✅","❌"))
A14: 12 | E14: =IF(ISBLANK(B14),"", IF(B14="Salud Completo",C14*1.5, IF(B14="Salud Completo Copago",C14*2, IF(B14="Salud Completo Copago Autónomo",C14*1.2, IF(B14="Contigo Senior",C14*3, IF(B14="Contigo Familia",C14*4, IF(B14="Contigo Autónomo (ILT)",C14*2, IF(B14="Plan Creciente SIALP",C14*1, IF(B14="MiHogar Seguro",C14*1.5, IF(B14="Líder Plus Accidentes",C14*4, IF(B14="Seguro Comercio y Oficinas - CASER",C14*0.5, IF(B14="Seguro Responsabilidad Civil - CASER",C14*0.4,0)))))))))))) | F14: =IF(ISBLANK(B14),"", IF(B14="Salud Completo",C14*0.16, IF(B14="Salud Completo Copago",C14*0.16, IF(B14="Salud Completo Copago Autónomo",C14*0.16, IF(B14="Contigo Senior", IF(D14="55-70 años",C14*1, IF(D14="71-75 años",C14*0.82, IF(D14="76-80 años",C14*0.7,0))), IF(B14="Contigo Familia",C14*1.5, IF(B14="Contigo Autónomo (ILT)",C14*0.75, IF(B14="Plan Creciente SIALP",C14*0.27, IF(B14="MiHogar Seguro",C14*1, IF(B14="Líder Plus Accidentes",C14*1.8, IF(B14="Seguro Comercio y Oficinas - CASER",C14*0.21, IF(B14="Seguro Responsabilidad Civil - CASER",C14*0.18,0)))))))))))) | G14: =IF(ISBLANK(B14),"", IF(B14="Salud Completo",F14*0.0112/12, IF(B14="Salud Completo Copago",F14*0.0112/12, IF(B14="Salud Completo Copago Autónomo",F14*0.0112/12, IF(B14="Contigo Senior", IF(D14="55-70 años",F14*0.07/12, IF(D14="71-75 años",F14*0.0574/12, IF(D14="76-80 años",F14*0.049/12,0))), IF(B14="Contigo Familia",F14*0.105/12, IF(B14="Contigo Autónomo (ILT)",F14*0.105/12, IF(B14="Plan Creciente SIALP",F14*0.0189, IF(B14="MiHogar Seguro",F14*0.042/12, IF(B14="Líder Plus Accidentes",F14*0.25/12, IF(B14="Seguro Comercio y Oficinas - CASER",F14*0.21/12, IF(B14="Seguro Responsabilidad Civil - CASER",F14*0.18/12,0)))))))))))) | H14: =IF(ISBLANK(B14),"", IF(OR(B14="Salud Completo",B14="Salud Completo Copago",B14="Salud Completo Copago Autónomo", B14="Contigo Senior",B14="Contigo Familia",B14="Contigo Autónomo (ILT)", B14="MiHogar Seguro",B14="Líder Plus Accidentes"),"✅","❌"))
A15: 13 | E15: =IF(ISBLANK(B15),"", IF(B15="Salud Completo",C15*1.5, IF(B15="Salud Completo Copago",C15*2, IF(B15="Salud Completo Copago Autónomo",C15*1.2, IF(B15="Contigo Senior",C15*3, IF(B15="Contigo Familia",C15*4, IF(B15="Contigo Autónomo (ILT)",C15*2, IF(B15="Plan Creciente SIALP",C15*1, IF(B15="MiHogar Seguro",C15*1.5, IF(B15="Líder Plus Accidentes",C15*4, IF(B15="Seguro Comercio y Oficinas - CASER",C15*0.5, IF(B15="Seguro Responsabilidad Civil - CASER",C15*0.4,0)))))))))))) | F15: =IF(ISBLANK(B15),"", IF(B15="Salud Completo",C15*0.16, IF(B15="Salud Completo Copago",C15*0.16, IF(B15="Salud Completo Copago Autónomo",C15*0.16, IF(B15="Contigo Senior", IF(D15="55-70 años",C15*1, IF(D15="71-75 años",C15*0.82, IF(D15="76-80 años",C15*0.7,0))), IF(B15="Contigo Familia",C15*1.5, IF(B15="Contigo Autónomo (ILT)",C15*0.75, IF(B15="Plan Creciente SIALP",C15*0.27, IF(B15="MiHogar Seguro",C15*1, IF(B15="Líder Plus Accidentes",C15*1.8, IF(B15="Seguro Comercio y Oficinas - CASER",C15*0.21, IF(B15="Seguro Responsabilidad Civil - CASER",C15*0.18,0)))))))))))) | G15: =IF(ISBLANK(B15),"", IF(B15="Salud Completo",F15*0.0112/12, IF(B15="Salud Completo Copago",F15*0.0112/12, IF(B15="Salud Completo Copago Autónomo",F15*0.0112/12, IF(B15="Contigo Senior", IF(D15="55-70 años",F15*0.07/12, IF(D15="71-75 años",F15*0.0574/12, IF(D15="76-80 años",F15*0.049/12,0))), IF(B15="Contigo Familia",F15*0.105/12, IF(B15="Contigo Autónomo (ILT)",F15*0.105/12, IF(B15="Plan Creciente SIALP",F15*0.0189, IF(B15="MiHogar Seguro",F15*0.042/12, IF(B15="Líder Plus Accidentes",F15*0.25/12, IF(B15="Seguro Comercio y Oficinas - CASER",F15*0.21/12, IF(B15="Seguro Responsabilidad Civil - CASER",F15*0.18/12,0)))))))))))) | H15: =IF(ISBLANK(B15),"", IF(OR(B15="Salud Completo",B15="Salud Completo Copago",B15="Salud Completo Copago Autónomo", B15="Contigo Senior",B15="Contigo Familia",B15="Contigo Autónomo (ILT)", B15="MiHogar Seguro",B15="Líder Plus Accidentes"),"✅","❌"))
A16: 14 | E16: =IF(ISBLANK(B16),"", IF(B16="Salud Completo",C16*1.5, IF(B16="Salud Completo Copago",C16*2, IF(B16="Salud Completo Copago Autónomo",C16*1.2, IF(B16="Contigo Senior",C16*3, IF(B16="Contigo Familia",C16*4, IF(B16="Contigo Autónomo (ILT)",C16*2, IF(B16="Plan Creciente SIALP",C16*1, IF(B16="MiHogar Seguro",C16*1.5, IF(B16="Líder Plus Accidentes",C16*4, IF(B16="Seguro Comercio y Oficinas - CASER",C16*0.5, IF(B16="Seguro Responsabilidad Civil - CASER",C16*0.4,0)))))))))))) | F16: =IF(ISBLANK(B16),"", IF(B16="Salud Completo",C16*0.16, IF(B16="Salud Completo Copago",C16*0.16, IF(B16="Salud Completo Copago Autónomo",C16*0.16, IF(B16="Contigo Senior", IF(D16="55-70 años",C16*1, IF(D16="71-75 años",C16*0.82, IF(D16="76-80 años",C16*0.7,0))), IF(B16="Contigo Familia",C16*1.5, IF(B16="Contigo Autónomo (ILT)",C16*0.75, IF(B16="Plan Creciente SIALP",C16*0.27, IF(B16="MiHogar Seguro",C16*1, IF(B16="Líder Plus Accidentes",C16*1.8, IF(B16="Seguro Comercio y Oficinas - CASER",C16*0.21, IF(B16="Seguro Responsabilidad Civil - CASER",C16*0.18,0)))))))))))) | G16: =IF(ISBLANK(B16),"", IF(B16="Salud Completo",F16*0.0112/12, IF(B16="Salud Completo Copago",F16*0.0112/12, IF(B16="Salud Completo Copago Autónomo",F16*0.0112/12, IF(B16="Contigo Senior", IF(D16="55-70 años",F16*0.07/12, IF(D16="71-75 años",F16*0.0574/12, IF(D16="76-80 años",F16*0.049/12,0))), IF(B16="Contigo Familia",F16*0.105/12, IF(B16="Contigo Autónomo (ILT)",F16*0.105/12, IF(B16="Plan Creciente SIALP",F16*0.0189, IF(B16="MiHogar Seguro",F16*0.042/12, IF(B16="Líder Plus Accidentes",F16*0.25/12, IF(B16="Seguro Comercio y Oficinas - CASER",F16*0.21/12, IF(B16="Seguro Responsabilidad Civil - CASER",F16*0.18/12,0)))))))))))) | H16: =IF(ISBLANK(B16),"", IF(OR(B16="Salud Completo",B16="Salud Completo Copago",B16="Salud Completo Copago Autónomo", B16="Contigo Senior",B16="Contigo Familia",B16="Contigo Autónomo (ILT)", B16="MiHogar Seguro",B16="Líder Plus Accidentes"),"✅","❌"))
A17: 15 | E17: =IF(ISBLANK(B17),"", IF(B17="Salud Completo",C17*1.5, IF(B17="Salud Completo Copago",C17*2, IF(B17="Salud Completo Copago Autónomo",C17*1.2, IF(B17="Contigo Senior",C17*3, IF(B17="Contigo Familia",C17*4, IF(B17="Contigo Autónomo (ILT)",C17*2, IF(B17="Plan Creciente SIALP",C17*1, IF(B17="MiHogar Seguro",C17*1.5, IF(B17="Líder Plus Accidentes",C17*4, IF(B17="Seguro Comercio y Oficinas - CASER",C17*0.5, IF(B17="Seguro Responsabilidad Civil - CASER",C17*0.4,0)))))))))))) | F17: =IF(ISBLANK(B17),"", IF(B17="Salud Completo",C17*0.16, IF(B17="Salud Completo Copago",C17*0.16, IF(B17="Salud Completo Copago Autónomo",C17*0.16, IF(B17="Contigo Senior", IF(D17="55-70 años",C17*1, IF(D17="71-75 años",C17*0.82, IF(D17="76-80 años",C17*0.7,0))), IF(B17="Contigo Familia",C17*1.5, IF(B17="Contigo Autónomo (ILT)",C17*0.75, IF(B17="Plan Creciente SIALP",C17*0.27, IF(B17="MiHogar Seguro",C17*1, IF(B17="Líder Plus Accidentes",C17*1.8, IF(B17="Seguro Comercio y Oficinas - CASER",C17*0.21, IF(B17="Seguro Responsabilidad Civil - CASER",C17*0.18,0)))))))))))) | G17: =IF(ISBLANK(B17),"", IF(B17="Salud Completo",F17*0.0112/12, IF(B17="Salud Completo Copago",F17*0.0112/12, IF(B17="Salud Completo Copago Autónomo",F17*0.0112/12, IF(B17="Contigo Senior", IF(D17="55-70 años",F17*0.07/12, IF(D17="71-75 años",F17*0.0574/12, IF(D17="76-80 años",F17*0.049/12,0))), IF(B17="Contigo Familia",F17*0.105/12, IF(B17="Contigo Autónomo (ILT)",F17*0.105/12, IF(B17="Plan Creciente SIALP",F17*0.0189, IF(B17="MiHogar Seguro",F17*0.042/12, IF(B17="Líder Plus Accidentes",F17*0.25/12, IF(B17="Seguro Comercio y Oficinas - CASER",F17*0.21/12, IF(B17="Seguro Responsabilidad Civil - CASER",F17*0.18/12,0)))))))))))) | H17: =IF(ISBLANK(B17),"", IF(OR(B17="Salud Completo",B17="Salud Completo Copago",B17="Salud Completo Copago Autónomo", B17="Contigo Senior",B17="Contigo Familia",B17="Contigo Autónomo (ILT)", B17="MiHogar Seguro",B17="Líder Plus Accidentes"),"✅","❌"))
... A22: 20 | E22: =IF(ISBLANK(B22),"", IF(B22="Salud Completo",C22*1.5, IF(B22="Salud Completo Copago",C22*2, IF(B22="Salud Completo Copago Autónomo",C22*1.2, IF(B22="Contigo Senior",C22*3, IF(B22="Contigo Familia",C22*4, IF(B22="Contigo Autónomo (ILT)",C22*2, IF(B22="Plan Creciente SIALP",C22*1, IF(B22="MiHogar Seguro",C22*1.5, IF(B22="Líder Plus Accidentes",C22*4, IF(B22="Seguro Comercio y Oficinas - CASER",C22*0.5, IF(B22="Seguro Responsabilidad Civil - CASER",C22*0.4,0)))))))))))) | F22: =IF(ISBLANK(B22),"", IF(B22="Salud Completo",C22*0.16, IF(B22="Salud Completo Copago",C22*0.16, IF(B22="Salud Completo Copago Autónomo",C22*0.16, IF(B22="Contigo Senior", IF(D22="55-70 años",C22*1, IF(D22="71-75 años",C22*0.82, IF(D22="76-80 años",C22*0.7,0))), IF(B22="Contigo Familia",C22*1.5, IF(B22="Contigo Autónomo (ILT)",C22*0.75, IF(B22="Plan Creciente SIALP",C22*0.27, IF(B22="MiHogar Seguro",C22*1, IF(B22="Líder Plus Accidentes",C22*1.8, IF(B22="Seguro Comercio y Oficinas - CASER",C22*0.21, IF(B22="Seguro Responsabilidad Civil - CASER",C22*0.18,0)))))))))))) | G22: =IF(ISBLANK(B22),"", IF(B22="Salud Completo",F22*0.0112/12, IF(B22="Salud Completo Copago",F22*0.0112/12, IF(B22="Salud Completo Copago Autónomo",F22*0.0112/12, IF(B22="Contigo Senior", IF(D22="55-70 años",F22*0.07/12, IF(D22="71-75 años",F22*0.0574/12, IF(D22="76-80 años",F22*0.049/12,0))), IF(B22="Contigo Familia",F22*0.105/12, IF(B22="Contigo Autónomo (ILT)",F22*0.105/12, IF(B22="Plan Creciente SIALP",F22*0.0189, IF(B22="MiHogar Seguro",F22*0.042/12, IF(B22="Líder Plus Accidentes",F22*0.25/12, IF(B22="Seguro Comercio y Oficinas - CASER",F22*0.21/12, IF(B22="Seguro Responsabilidad Civil - CASER",F22*0.18/12,0)))))))))))) | H22: =IF(ISBLANK(B22),"", IF(OR(B22="Salud Completo",B22="Salud Completo Copago",B22="Salud Completo Copago Autónomo", B22="Contigo Senior",B22="Contigo Familia",B22="Contigo Autónomo (ILT)", B22="MiHogar Seguro",B22="Líder Plus Accidentes"),"✅","❌"))
J24: ESTADO MENSUAL
L25: =COUNTA(B3:B22) -> 3
J26: Operaciones cerradas: | L26: =SUM(E3:E22) -> 5930
J27: PVM Acumulado: | L27: 10291 | M27: pts
J28: Objetivo mes: | L28: =L26/L27 -> 0.57623166 | M28: pts
J29: % Completado: | L29: =MAX(0,L27-L26) -> 4361 | M29: =IF(L29>=0.9,"🟢",IF(L29>=0.7,"🟡","🔴")) -> 🟢
J30: Faltan: | L30: =MAX(0,L28-L26) -> 0 | M30: pts
J32: PVM Riesgo: | L32: =SUMIF(H3:H22,"✅",E3:E22) -> 3930 | M32: =IF(L26=0,"0%",ROUND(L32/L26,0)&"%") -> 1%
J33: Mínimo Riesgo (50%): | L33: =L27*0.5 -> 5145.5 | M33: pts
J35: PROYECCIÓN INGRESO MENSUAL
J36: Anticipo base: | L36: =IF(AND(L26>=L27*0.9,L32/L26>=0.45),900, IF(AND(L26>=L27*0.7,L32/L26>=0.4),700,0)) -> 0 | M36: €
J37: Compensación PN: | L37: =IF(AND(L26>=L27,L32/L26>=0.5),300,0) -> 0 | M37: €
J38: Complemento Riesgo: | L38: =IF(L32/L26>=1,550, IF(L32/L26>=0.85,450, IF(L32/L26>=0.75,300, IF(L32/L26>=0.65,200, IF(L32/L26>=0.5,100, IF(L32/L26>=0.4,0, IF(L32/L26>=0.35,-100,-200))))))) -> 200 | M38: €
J39: Comisión Tramos: | L39: =SUM(F3:F22)*0.08 -> 98.624 | M39: €
J40: Comisión Básica: | L40: =SUM(G3:G22) -> 12.440213 | M40: €
J42: BRUTO Total: | L42: =L36+L37+L38+L39+L40 -> 311.06421 | M42: €
J43: - IRPF 15%: | L43: =-L42*0.15 -> -46.659632 | M43: €
J45: 💰 NETO EN BANCO: | L45: =L42+L43 -> 264.40458 | M45: €
J48: ESTADO SEMANAL
J50: Semana actual: | L50: 1 | M50: de 4
J52: PVM esta semana: | K52: (editar manual) | L52: 0 | M52: pts
J53: Objetivo semanal: | L53: =ROUND(L28/4,0) -> 0 | M53: pts
...

Sheet Equipo
A1: OPERACIONES DEL MES
A2: # | B2: Producto | C2: Prima/año € | D2: Edad | E2: PVM | F2: Riesgo
A3: ='Mi Sprint'!A3 -> 1 | B3: ='Mi Sprint'!B3 -> Salud Completo | C3: ='Mi Sprint'!C3 -> 1180 | D3: ='Mi Sprint'!D3 -> 0 | E3: ='Mi Sprint'!E3 -> 1770 | F3: ='Mi Sprint'!H3 -> ✅
A4: ='Mi Sprint'!A4 -> 2 | B4: ='Mi Sprint'!B4 -> Contigo Senior | C4: ='Mi Sprint'!C4 -> 720 | D4: ='Mi Sprint'!D4 -> 76-80 años | E4: ='Mi Sprint'!E4 -> 2160 | F4: ='Mi Sprint'!H4 -> ✅
A5: ='Mi Sprint'!A5 -> 3 | B5: ='Mi Sprint'!B5 -> Plan Creciente SIALP | C5: ='Mi Sprint'!C5 -> 2000 | D5: ='Mi Sprint'!D5 -> 0 | E5: ='Mi Sprint'!E5 -> 2000 | F5: ='Mi Sprint'!H5 -> ❌
A6: ='Mi Sprint'!A6 -> 4 | B6: ='Mi Sprint'!B6 -> 0 | C6: ='Mi Sprint'!C6 -> 0 | D6: ='Mi Sprint'!D6 -> 0 | E6: ='Mi Sprint'!E6 | F6: ='Mi Sprint'!H6
A7: ='Mi Sprint'!A7 -> 5 | B7: ='Mi Sprint'!B7 -> 0 | C7: ='Mi Sprint'!C7 -> 0 | D7: ='Mi Sprint'!D7 -> 0 | E7: ='Mi Sprint'!E7 | F7: ='Mi Sprint'!H7
A8: ='Mi Sprint'!A8 -> 6 | B8: ='Mi Sprint'!B8 -> 0 | C8: ='Mi Sprint'!C8 -> 0 | D8: ='Mi Sprint'!D8 -> 0 | E8: ='Mi Sprint'!E8 | F8: ='Mi Sprint'!H8
A9: ='Mi Sprint'!A9 -> 7 | B9: ='Mi Sprint'!B9 -> 0 | C9: ='Mi Sprint'!C9 -> 0 | D9: ='Mi Sprint'!D9 -> 0 | E9: ='Mi Sprint'!E9 | F9: ='Mi Sprint'!H9
A10: ='Mi Sprint'!A10 -> 8 | B10: ='Mi Sprint'!B10 -> 0 | C10: ='Mi Sprint'!C10 -> 0 | D10: ='Mi Sprint'!D10 -> 0 | E10: ='Mi Sprint'!E10 | F10: ='Mi Sprint'!H10
A11: ='Mi Sprint'!A11 -> 9 | B11: ='Mi Sprint'!B11 -> 0 | C11: ='Mi Sprint'!C11 -> 0 | D11: ='Mi Sprint'!D11 -> 0 | E11: ='Mi Sprint'!E11 | F11: ='Mi Sprint'!H11
A12: ='Mi Sprint'!A12 -> 10 | B12: ='Mi Sprint'!B12 -> 0 | C12: ='Mi Sprint'!C12 -> 0 | D12: ='Mi Sprint'!D12 -> 0 | E12: ='Mi Sprint'!E12 | F12: ='Mi Sprint'!H12
A13: ='Mi Sprint'!A13 -> 11 | B13: ='Mi Sprint'!B13 -> 0 | C13: ='Mi Sprint'!C13 -> 0 | D13: ='Mi Sprint'!D13 -> 0 | E13: ='Mi Sprint'!E13 | F13: ='Mi Sprint'!H13
A14: ='Mi Sprint'!A14 -> 12 | B14: ='Mi Sprint'!B14 -> 0 | C14: ='Mi Sprint'!C14 -> 0 | D14: ='Mi Sprint'!D14 -> 0 | E14: ='Mi Sprint'!E14 | F14: ='Mi Sprint'!H14
... A22: ='Mi Sprint'!A22 -> 20 | B22: ='Mi Sprint'!B22 -> 0 | C22: ='Mi Sprint'!C22 -> 0 | D22: ='Mi Sprint'!D22 -> 0 | E22: ='Mi Sprint'!E22 | F22: ='Mi Sprint'!H22
A24: RESUMEN DEL MES
A26: Operaciones cerradas: | C26: =COUNTA(B3:B22) -> 20
A27: PVM Acumulado: | C27: =SUM(E3:E22) -> 5930 | D27: pts
A28: Objetivo mes: | C28: 10291 | D28: pts
A29: % Completado: | C29: =C27/C28 -> 0.57623166 | D29: =IF(C29>=0.9,"🟢",IF(C29>=0.7,"🟡","🔴")) -> 🔴
A30: Faltan: | C30: =MAX(0,C28-C27) -> 4361 | D30: pts
A32: PVM Riesgo: | C32: =SUMIF(F3:F22,"✅",E3:E22) -> 3930 | D32: =IF(C27=0,"0%",ROUND(C32/C27,0)&"%") -> 1%
A33: Mínimo Riesgo (50%): | C33: =C28*0.5 -> 5145.5 | D33: pts
A36: ESTADO SEMANAL
A38: Semana actual: | C38: 1 | D38: de 4
A40: PVM esta semana: | B40: (editar manual) | C40: 0 | D40: pts
A41: Objetivo semanal: | C41: =ROUND(C28/4,0) -> 2573 | D41: pts
A42: % Completado semana: | C42: =IF(C41=0,0,C40/C41) -> 0 | D42: =IF(C42>=0.9,"🟢",IF(C42>=0.7,"🟡","🔴")) -> 🔴
A43: Faltan esta semana: | C43: =MAX(0,C41-C40) -> 2573 | D43: pts
A45: Ritmo proyectado cierre mes:
A46: Si continúas a este ritmo: | C46: =C40*4 -> 0 | D46: =IF(C46>=C28,"✅","❌") -> ❌
A47: Necesitas acelerar: | C47: =IF((4-C38)<=0,0,MAX(0,(C28-C27)/(4-C38))) -> 1453.6667 | D47: pts/sem
